Workbook

Sheet Executive Summary
B2: NHS OPERATIONS | EXECUTIVE SUMMARY
B5: Published aggregate observations · independent portfolio analysis · source-specific reporting months
B7: LATEST VALIDATED PUBLICATIONS
B9: Domain / unit | C9: Reporting month | D9: Headline volume | E9: Performance
B10: RTT · pathways | C10: 2026-08 | D10: =SUMIFS(NationalData[RTT waiting],NationalData[Month],C10) -> 7158164 | E10: =IFERROR(SUMIFS(NationalData[RTT within18],NationalData[Month],C10)/SUMIFS(NationalData[RTT waiting],NationalData[Month],C10),"") -> 0.65206022
B11: A&E · attendances | C11: 2026-09 | D11: =SUMIFS(NationalData[AE attendances],NationalData[Month],C11) -> 2444743 | E11: =IFERROR(SUMIFS(NationalData[AE within4],NationalData[Month],C11)/SUMIFS(NationalData[AE attendances],NationalData[Month],C11),"") -> 0.74363318
B12: Diagnostics · waits | C12: 2026-08 | D12: =SUMIFS(NationalData[Diagnostic waiting],NationalData[Month],C12) -> 1833070 | E12: =IFERROR(SUMIFS(NationalData[Diagnostic over6],NationalData[Month],C12)/SUMIFS(NationalData[Diagnostic waiting],NationalData[Month],C12),"") -> 0.24674781
B14: RTT/A&E: higher performance is better. Diagnostics: lower six-week-or-more rate is better. Different populations and reporting dates; never sum headline volumes.
B18: Provider investigation | C18: RAJ
B19: Selected provider | C19: =_xlfn.XLOOKUP(C18,Providers[Provider code],Providers[Provider name],"Not in comparable cohort") -> MID AND SOUTH ESSEX NHS FOUNDATION TRUST
B21: Review signals | C21: =COUNTIFS(Providers[Review signal],"Review sustained deterioration") -> 55 | D21: Providers with sustained deterioration
B23: Management action: review long-wait concentration, diagnostic test bottlenecks and admission flow with local operational evidence. Signals are proposed investigations, not clinical-quality rankings.
B28: Source: NHS England RTT, monthly A&E and DM01. Official URLs, release evidence and checksum lineage are available on Data Quality Summary and in the repository manifest.

Sheet RTT Performance
B2: NHS OPERATIONS | RTT PERFORMANCE
B5: Published aggregate observations · independent portfolio analysis · source-specific reporting months
B8: Month | C8: Incomplete pathways | D8: Within18 | E8: Over52 | F8: Within18 rate
B9: 2024-09 | C9: 7571549 | D9: 4429902 | E9: 249024 | F9: =IFERROR($D9/$C9,"") -> 0.58507209
B10: 2024-10 | C10: 7541371 | D10: 4444500 | E10: 234914 | F10: =IFERROR($D10/$C10,"") -> 0.58934907
B11: 2024-11 | C11: 7479867 | D11: 4424701 | E11: 221567 | F11: =IFERROR($D11/$C11,"") -> 0.59154809
B12: 2024-12 | C12: 7463085 | D12: 4398544 | E12: 200402 | F12: =IFERROR($D12/$C12,"") -> 0.58937343
B13: 2025-01 | C13: 7427669 | D13: 4371844 | E13: 198828 | F13: =IFERROR($D13/$C13,"") -> 0.58858896
B14: 2025-02 | C14: 7401153 | D14: 4379951 | E14: 193525 | F14: =IFERROR($D14/$C14,"") -> 0.59179306
B15: 2025-03 | C15: 7418598 | D15: 4434722 | E15: 180243 | F15: =IFERROR($D15/$C15,"") -> 0.59778438
B16: 2025-04 | C16: 7389065 | D16: 4413682 | E16: 190023 | F16: =IFERROR($D16/$C16,"") -> 0.59732618
B17: 2025-05 | C17: 7355950 | D17: 4482076 | E17: 196839 | F17: =IFERROR($D17/$C17,"") -> 0.60931301
B18: 2025-06 | C18: 7367836 | D18: 4533070 | E18: 191755 | F18: =IFERROR($D18/$C18,"") -> 0.61525121
B19: 2025-07 | C19: 7299023 | D19: 4468469 | E19: 189416 | F19: =IFERROR($D19/$C19,"") -> 0.61220098
B20: 2025-08 | C20: 7312356 | D20: 4458454 | E20: 188702 | F20: =IFERROR($D20/$C20,"") -> 0.60971512
... B32: 2026-08 | C32: 7158164 | D32: 4667554 | E32: 109936 | F32: =IFERROR($D32/$C32,"") -> 0.65206022

Sheet A&E Performance
B2: NHS OPERATIONS | A&E PERFORMANCE
B5: Published aggregate observations · independent portfolio analysis · source-specific reporting months
B8: Month | C8: Attendances | D8: Within4 | E8: Emergency admissions | F8: DTA12plus | G8: Within4 rate
B9: 2024-09 | C9: 2214217 | D9: 1643329 | E9: 530824 | F9: 38880 | G9: =IFERROR($D9/$C9,"") -> 0.74217161
B10: 2024-10 | C10: 2360536 | D10: 1725194 | E10: 567448 | F10: 49616 | G10: =IFERROR($D10/$C10,"") -> 0.73084842
B11: 2024-11 | C11: 2314998 | D11: 1671002 | E11: 552161 | F11: 45791 | G11: =IFERROR($D11/$C11,"") -> 0.72181574
B12: 2024-12 | C12: 2345934 | D12: 1668461 | E12: 552592 | F12: 54207 | G12: =IFERROR($D12/$C12,"") -> 0.71121396
B13: 2025-01 | C13: 2218130 | D13: 1619384 | E13: 548775 | F13: 61529 | G13: =IFERROR($D13/$C13,"") -> 0.73006722
B14: 2025-02 | C14: 2088071 | D14: 1533925 | E14: 496095 | F14: 47623 | G14: =IFERROR($D14/$C14,"") -> 0.73461343
B15: 2025-03 | C15: 2389064 | D15: 1791316 | E15: 551129 | F15: 46766 | G15: =IFERROR($D15/$C15,"") -> 0.74979825
B16: 2025-04 | C16: 2297421 | D16: 1718099 | E16: 528230 | F16: 44648 | G16: =IFERROR($D16/$C16,"") -> 0.74783812
B17: 2025-05 | C17: 2397529 | D17: 1807794 | E17: 545128 | F17: 42891 | G17: =IFERROR($D17/$C17,"") -> 0.75402383
B18: 2025-06 | C18: 2351581 | D18: 1776772 | E18: 535941 | F18: 38683 | G18: =IFERROR($D18/$C18,"") -> 0.75556487
B19: 2025-07 | C19: 2408866 | D19: 1840562 | E19: 559392 | F19: 35467 | G19: =IFERROR($D19/$C19,"") -> 0.7640782
B20: 2025-08 | C20: 2266937 | D20: 1720066 | E20: 526399 | F20: 35909 | G20: =IFERROR($D20/$C20,"") -> 0.75876215
... B33: 2026-09 | C33: 2444743 | D33: 1817992 | E33: 536158 | F33: 50582 | G33: =IFERROR($D33/$C33,"") -> 0.74363318

Sheet Diagnostics Performance
B2: NHS OPERATIONS | DIAGNOSTICS PERFORMANCE
B5: Published aggregate observations · independent portfolio analysis · source-specific reporting months
B8: Month | C8: Waiting list | D8: Six weeks or more | E8: Activity | F8: Six-week rate
B9: 2024-09 | C9: 1592553 | D9: 361264 | E9: 2393472 | F9: =IFERROR($D9/$C9,"") -> 0.22684583
B10: 2024-10 | C10: 1636424 | D10: 338730 | E10: 2568267 | F10: =IFERROR($D10/$C10,"") -> 0.20699403
B11: 2024-11 | C11: 1620824 | D11: 322929 | E11: 2465088 | F11: =IFERROR($D11/$C11,"") -> 0.19923755
B12: 2024-12 | C12: 1568661 | D12: 357119 | E12: 2257697 | F12: =IFERROR($D12/$C12,"") -> 0.22765849
B13: 2025-01 | C13: 1627995 | D13: 365178 | E13: 2539567 | F13: =IFERROR($D13/$C13,"") -> 0.2243115
B14: 2025-02 | C14: 1674823 | D14: 292432 | E14: 2354255 | F14: =IFERROR($D14/$C14,"") -> 0.17460472
B15: 2025-03 | C15: 1709380 | D15: 313990 | E15: 2526281 | F15: =IFERROR($D15/$C15,"") -> 0.18368648
B16: 2025-04 | C16: 1703100 | D16: 361993 | E16: 2429486 | F16: =IFERROR($D16/$C16,"") -> 0.21254947
B17: 2025-05 | C17: 1715934 | D17: 378352 | E17: 2500593 | F17: =IFERROR($D17/$C17,"") -> 0.22049333
B18: 2025-06 | C18: 1739272 | D18: 370874 | E18: 2529788 | F18: =IFERROR($D18/$C18,"") -> 0.21323519
B19: 2025-07 | C19: 1753665 | D19: 383518 | E19: 2662297 | F19: =IFERROR($D19/$C19,"") -> 0.21869513
B20: 2025-08 | C20: 1683852 | D20: 404795 | E20: 2422424 | F20: =IFERROR($D20/$C20,"") -> 0.24039821
... B32: 2026-08 | C32: 1833070 | D32: 452306 | E32: 2516963 | F32: =IFERROR($D32/$C32,"") -> 0.24674781

Sheet Provider Comparisons
B2: NHS OPERATIONS | PROVIDER COMPARISONS
B5: Published aggregate observations · independent portfolio analysis · source-specific reporting months
B8: Provider code | C8: Provider name | D8: RTT pathways | E8: Within18 | F8: Over52 | G8: Review signal | H8: Within18 rate | J8: Row Labels | K8: Pathways by signal | L8: Over52 by signal
B9: RAJ | C9: MID AND SOUTH ESSEX NHS FOUNDATION TRUST | D9: 165234 | E9: 83209 | F9: 13426 | G9: Review long-wait volume | H9: =IFERROR($E9/$D9,"") -> 0.5035828 | J9: Monitor | K9: 3581937 | L9: 30224
B10: RYR | C10: UNIVERSITY HOSPITALS SUSSEX NHS FOUNDATION TRUST | D10: 118139 | E10: 62176 | F10: 5634 | G10: Review sustained deterioration | H10: =IFERROR($E10/$D10,"") -> 0.5262953 | J10: Review long-wait volume | K10: 1920814 | L10: 48784
B11: RM3 | C11: NORTHERN CARE ALLIANCE NHS FOUNDATION TRUST | D11: 136819 | E11: 76293 | F11: 3928 | G11: Review sustained deterioration | H11: =IFERROR($E11/$D11,"") -> 0.55761992 | J11: Review sustained deterioration | K11: 1552489 | L11: 30273
B12: RWA | C12: HULL UNIVERSITY TEACHING HOSPITALS NHS TRUST | D12: 86732 | E12: 48083 | F12: 3500 | G12: Review sustained deterioration | H12: =IFERROR($E12/$D12,"") -> 0.55438592 | J12: Grand Total | K12: 7055240 | L12: 109281
B13: RVV | C13: EAST KENT HOSPITALS UNIVERSITY NHS FOUNDATION TRUST | D13: 85362 | E13: 47313 | F13: 2623 | G13: Review long-wait volume | H13: =IFERROR($E13/$D13,"") -> 0.55426302
B14: RWE | C14: UNIVERSITY HOSPITALS OF LEICESTER NHS TRUST | D14: 114859 | E14: 69201 | F14: 2454 | G14: Review long-wait volume | H14: =IFERROR($E14/$D14,"") -> 0.60248653
B15: RX1 | C15: NOTTINGHAM UNIVERSITY HOSPITALS NHS TRUST | D15: 86339 | E15: 53655 | F15: 2404 | G15: Review long-wait volume | H15: =IFERROR($E15/$D15,"") -> 0.6214457
B16: RTG | C16: UNIVERSITY HOSPITALS OF DERBY AND BURTON NHS FOUNDATION TRUST | D16: 100816 | E16: 61257 | F16: 2176 | G16: Review long-wait volume | H16: =IFERROR($E16/$D16,"") -> 0.60761189
B17: RKB | C17: UNIVERSITY HOSPITALS COVENTRY AND WARWICKSHIRE NHS TRUST | D17: 66585 | E17: 39135 | F17: 2173 | G17: Review long-wait volume | H17: =IFERROR($E17/$D17,"") -> 0.58774499
B18: RJZ | C18: KING'S COLLEGE HOSPITAL NHS FOUNDATION TRUST | D18: 91060 | E18: 60305 | F18: 2004 | G18: Review long-wait volume | H18: =IFERROR($E18/$D18,"") -> 0.66225566
B19: RHU | C19: PORTSMOUTH HOSPITALS UNIVERSITY NHS TRUST | D19: 57574 | E19: 34910 | F19: 1863 | G19: Review long-wait volume | H19: =IFERROR($E19/$D19,"") -> 0.60635009
B20: RM1 | C20: NORFOLK AND NORWICH UNIVERSITY HOSPITALS NHS FOUNDATION TRUST | D20: 66055 | E20: 41962 | F20: 1802 | G20: Review long-wait volume | H20: =IFERROR($E20/$D20,"") -> 0.6352585
B21: RBN | C21: MERSEY AND WEST LANCASHIRE TEACHING HOSPITALS NHS TRUST | D21: 83764 | E21: 54482 | F21: 1752 | G21: Review sustained deterioration | H21: =IFERROR($E21/$D21,"") -> 0.65042262
B22: RJE | C22: UNIVERSITY HOSPITALS OF NORTH MIDLANDS NHS TRUST | D22: 75383 | E22: 45220 | F22: 1735 | G22: Review sustained deterioration | H22: =IFERROR($E22/$D22,"") -> 0.59987
B23: RH5 | C23: SOMERSET NHS FOUNDATION TRUST | D23: 55374 | E23: 35493 | F23: 1702 | G23: Review sustained deterioration | H23: =IFERROR($E23/$D23,"") -> 0.64096869
B24: RH8 | C24: ROYAL DEVON UNIVERSITY HEALTHCARE NHS FOUNDATION TRUST | D24: 74495 | E24: 46755 | F24: 1684 | G24: Review long-wait volume | H24: =IFERROR($E24/$D24,"") -> 0.62762602
... B278: RYY | C278: KENT COMMUNITY HEALTH NHS FOUNDATION TRUST | D278: 4655 | E278: 4644 | F278: 0 | G278: Monitor | H278: =IFERROR($E278/$D278,"") -> 0.99763695

Sheet Monthly Trends
B2: NHS OPERATIONS | MONTHLY TRENDS
B5: Published aggregate observations · independent portfolio analysis · source-specific reporting months
B8: Month | C8: RTT within18 rate | D8: AE within4 rate | E8: Diagnostics six-week rate
B9: 2024-09 | C9: =IFERROR(SUMIFS(NationalData[RTT within18],NationalData[Month],B9)/SUMIFS(NationalData[RTT waiting],NationalData[Month],B9),"") -> 0.58507209 | D9: =IFERROR(SUMIFS(NationalData[AE within4],NationalData[Month],B9)/SUMIFS(NationalData[AE attendances],NationalData[Month],B9),"") -> 0.74217161 | E9: =IFERROR(SUMIFS(NationalData[Diagnostic over6],NationalData[Month],B9)/SUMIFS(NationalData[Diagnostic waiting],NationalData[Month],B9),"") -> 0.22684583
B10: 2024-10 | C10: =IFERROR(SUMIFS(NationalData[RTT within18],NationalData[Month],B10)/SUMIFS(NationalData[RTT waiting],NationalData[Month],B10),"") -> 0.58934907 | D10: =IFERROR(SUMIFS(NationalData[AE within4],NationalData[Month],B10)/SUMIFS(NationalData[AE attendances],NationalData[Month],B10),"") -> 0.73084842 | E10: =IFERROR(SUMIFS(NationalData[Diagnostic over6],NationalData[Month],B10)/SUMIFS(NationalData[Diagnostic waiting],NationalData[Month],B10),"") -> 0.20699403
B11: 2024-11 | C11: =IFERROR(SUMIFS(NationalData[RTT within18],NationalData[Month],B11)/SUMIFS(NationalData[RTT waiting],NationalData[Month],B11),"") -> 0.59154809 | D11: =IFERROR(SUMIFS(NationalData[AE within4],NationalData[Month],B11)/SUMIFS(NationalData[AE attendances],NationalData[Month],B11),"") -> 0.72181574 | E11: =IFERROR(SUMIFS(NationalData[Diagnostic over6],NationalData[Month],B11)/SUMIFS(NationalData[Diagnostic waiting],NationalData[Month],B11),"") -> 0.19923755
B12: 2024-12 | C12: =IFERROR(SUMIFS(NationalData[RTT within18],NationalData[Month],B12)/SUMIFS(NationalData[RTT waiting],NationalData[Month],B12),"") -> 0.58937343 | D12: =IFERROR(SUMIFS(NationalData[AE within4],NationalData[Month],B12)/SUMIFS(NationalData[AE attendances],NationalData[Month],B12),"") -> 0.71121396 | E12: =IFERROR(SUMIFS(NationalData[Diagnostic over6],NationalData[Month],B12)/SUMIFS(NationalData[Diagnostic waiting],NationalData[Month],B12),"") -> 0.22765849
B13: 2025-01 | C13: =IFERROR(SUMIFS(NationalData[RTT within18],NationalData[Month],B13)/SUMIFS(NationalData[RTT waiting],NationalData[Month],B13),"") -> 0.58858896 | D13: =IFERROR(SUMIFS(NationalData[AE within4],NationalData[Month],B13)/SUMIFS(NationalData[AE attendances],NationalData[Month],B13),"") -> 0.73006722 | E13: =IFERROR(SUMIFS(NationalData[Diagnostic over6],NationalData[Month],B13)/SUMIFS(NationalData[Diagnostic waiting],NationalData[Month],B13),"") -> 0.2243115
B14: 2025-02 | C14: =IFERROR(SUMIFS(NationalData[RTT within18],NationalData[Month],B14)/SUMIFS(NationalData[RTT waiting],NationalData[Month],B14),"") -> 0.59179306 | D14: =IFERROR(SUMIFS(NationalData[AE within4],NationalData[Month],B14)/SUMIFS(NationalData[AE attendances],NationalData[Month],B14),"") -> 0.73461343 | E14: =IFERROR(SUMIFS(NationalData[Diagnostic over6],NationalData[Month],B14)/SUMIFS(NationalData[Diagnostic waiting],NationalData[Month],B14),"") -> 0.17460472
B15: 2025-03 | C15: =IFERROR(SUMIFS(NationalData[RTT within18],NationalData[Month],B15)/SUMIFS(NationalData[RTT waiting],NationalData[Month],B15),"") -> 0.59778438 | D15: =IFERROR(SUMIFS(NationalData[AE within4],NationalData[Month],B15)/SUMIFS(NationalData[AE attendances],NationalData[Month],B15),"") -> 0.74979825 | E15: =IFERROR(SUMIFS(NationalData[Diagnostic over6],NationalData[Month],B15)/SUMIFS(NationalData[Diagnostic waiting],NationalData[Month],B15),"") -> 0.18368648
B16: 2025-04 | C16: =IFERROR(SUMIFS(NationalData[RTT within18],NationalData[Month],B16)/SUMIFS(NationalData[RTT waiting],NationalData[Month],B16),"") -> 0.59732618 | D16: =IFERROR(SUMIFS(NationalData[AE within4],NationalData[Month],B16)/SUMIFS(NationalData[AE attendances],NationalData[Month],B16),"") -> 0.74783812 | E16: =IFERROR(SUMIFS(NationalData[Diagnostic over6],NationalData[Month],B16)/SUMIFS(NationalData[Diagnostic waiting],NationalData[Month],B16),"") -> 0.21254947
B17: 2025-05 | C17: =IFERROR(SUMIFS(NationalData[RTT within18],NationalData[Month],B17)/SUMIFS(NationalData[RTT waiting],NationalData[Month],B17),"") -> 0.60931301 | D17: =IFERROR(SUMIFS(NationalData[AE within4],NationalData[Month],B17)/SUMIFS(NationalData[AE attendances],NationalData[Month],B17),"") -> 0.75402383 | E17: =IFERROR(SUMIFS(NationalData[Diagnostic over6],NationalData[Month],B17)/SUMIFS(NationalData[Diagnostic waiting],NationalData[Month],B17),"") -> 0.22049333
B18: 2025-06 | C18: =IFERROR(SUMIFS(NationalData[RTT within18],NationalData[Month],B18)/SUMIFS(NationalData[RTT waiting],NationalData[Month],B18),"") -> 0.61525121 | D18: =IFERROR(SUMIFS(NationalData[AE within4],NationalData[Month],B18)/SUMIFS(NationalData[AE attendances],NationalData[Month],B18),"") -> 0.75556487 | E18: =IFERROR(SUMIFS(NationalData[Diagnostic over6],NationalData[Month],B18)/SUMIFS(NationalData[Diagnostic waiting],NationalData[Month],B18),"") -> 0.21323519
B19: 2025-07 | C19: =IFERROR(SUMIFS(NationalData[RTT within18],NationalData[Month],B19)/SUMIFS(NationalData[RTT waiting],NationalData[Month],B19),"") -> 0.61220098 | D19: =IFERROR(SUMIFS(NationalData[AE within4],NationalData[Month],B19)/SUMIFS(NationalData[AE attendances],NationalData[Month],B19),"") -> 0.7640782 | E19: =IFERROR(SUMIFS(NationalData[Diagnostic over6],NationalData[Month],B19)/SUMIFS(NationalData[Diagnostic waiting],NationalData[Month],B19),"") -> 0.21869513
B20: 2025-08 | C20: =IFERROR(SUMIFS(NationalData[RTT within18],NationalData[Month],B20)/SUMIFS(NationalData[RTT waiting],NationalData[Month],B20),"") -> 0.60971512 | D20: =IFERROR(SUMIFS(NationalData[AE within4],NationalData[Month],B20)/SUMIFS(NationalData[AE attendances],NationalData[Month],B20),"") -> 0.75876215 | E20: =IFERROR(SUMIFS(NationalData[Diagnostic over6],NationalData[Month],B20)/SUMIFS(NationalData[Diagnostic waiting],NationalData[Month],B20),"") -> 0.24039821
... B33: 2026-09 | C33: =IFERROR(SUMIFS(NationalData[RTT within18],NationalData[Month],B33)/SUMIFS(NationalData[RTT waiting],NationalData[Month],B33),"") | D33: =IFERROR(SUMIFS(NationalData[AE within4],NationalData[Month],B33)/SUMIFS(NationalData[AE attendances],NationalData[Month],B33),"") -> 0.74363318 | E33: =IFERROR(SUMIFS(NationalData[Diagnostic over6],NationalData[Month],B33)/SUMIFS(NationalData[Diagnostic waiting],NationalData[Month],B33),"")

Sheet Operational Priorities
B2: NHS OPERATIONS | OPERATIONAL PRIORITIES
B5: Published aggregate observations · independent portfolio analysis · source-specific reporting months
B8: Code | C8: Provider | D8: Over52 | E8: Review signal
B9: RAJ | C9: MID AND SOUTH ESSEX NHS FOUNDATION TRUST | D9: 13426 | E9: Review long-wait volume
B10: RYR | C10: UNIVERSITY HOSPITALS SUSSEX NHS FOUNDATION TRUST | D10: 5634 | E10: Review sustained deterioration
B11: RM3 | C11: NORTHERN CARE ALLIANCE NHS FOUNDATION TRUST | D11: 3928 | E11: Review sustained deterioration
B12: RWA | C12: HULL UNIVERSITY TEACHING HOSPITALS NHS TRUST | D12: 3500 | E12: Review sustained deterioration
B13: RVV | C13: EAST KENT HOSPITALS UNIVERSITY NHS FOUNDATION TRUST | D13: 2623 | E13: Review long-wait volume
B14: RWE | C14: UNIVERSITY HOSPITALS OF LEICESTER NHS TRUST | D14: 2454 | E14: Review long-wait volume
B15: RX1 | C15: NOTTINGHAM UNIVERSITY HOSPITALS NHS TRUST | D15: 2404 | E15: Review long-wait volume
B16: RTG | C16: UNIVERSITY HOSPITALS OF DERBY AND BURTON NHS FOUNDATION TRUST | D16: 2176 | E16: Review long-wait volume
B17: RKB | C17: UNIVERSITY HOSPITALS COVENTRY AND WARWICKSHIRE NHS TRUST | D17: 2173 | E17: Review long-wait volume
B18: RJZ | C18: KING'S COLLEGE HOSPITAL NHS FOUNDATION TRUST | D18: 2004 | E18: Review long-wait volume
B19: RHU | C19: PORTSMOUTH HOSPITALS UNIVERSITY NHS TRUST | D19: 1863 | E19: Review long-wait volume
B20: RM1 | C20: NORFOLK AND NORWICH UNIVERSITY HOSPITALS NHS FOUNDATION TRUST | D20: 1802 | E20: Review long-wait volume
... B23: RH5 | C23: SOMERSET NHS FOUNDATION TRUST | D23: 1702 | E23: Review sustained deterioration
B26: Signals identify areas for investigation. Account for provider size, specialty mix, code changes and data validation before taking action.

Sheet KPI Definitions
B2: NHS OPERATIONS | KPI DEFINITIONS
B5: Published aggregate observations · independent portfolio analysis · source-specific reporting months
B8: KPI | C8: Meaning | D8: Numerator | E8: Denominator | F8: Caveat
B9: Incomplete RTT pathways | C9: Month-end pathways still waiting; counts pathways, not unique people | D9: SUM(waiting_count) | E9: Not applicable | F9: Submitted data; excludes missing-trust estimates; geographic parent is a source ICB, not a hospital site
B10: RTT within 18 weeks | C10: Incomplete pathways in weekly bands up to and including 18 weeks | D10: SUM(within_18) | E10: Not applicable | F10: Submitted data; excludes missing-trust estimates; geographic parent is a source ICB, not a hospital site
B11: RTT over 18 weeks | C11: Incomplete pathways strictly over 18 weeks | D11: SUM(over_18) | E11: Not applicable | F11: Submitted data; excludes missing-trust estimates; geographic parent is a source ICB, not a hospital site
B12: RTT over 52 weeks | C12: Incomplete pathways strictly over 52 weeks | D12: SUM(over_52) | E12: Not applicable | F12: Submitted data; excludes missing-trust estimates; geographic parent is a source ICB, not a hospital site
B13: RTT over 65 weeks | C13: Incomplete pathways strictly over 65 weeks | D13: SUM(over_65) | E13: Not applicable | F13: Submitted data; excludes missing-trust estimates; geographic parent is a source ICB, not a hospital site
B14: RTT over 78 weeks | C14: Incomplete pathways strictly over 78 weeks | D14: SUM(over_78) | E14: Not applicable | F14: Submitted data; excludes missing-trust estimates; geographic parent is a source ICB, not a hospital site
B15: RTT over 104 weeks | C15: Incomplete pathways strictly over 104 weeks | D15: SUM(over_104) | E15: Not applicable | F15: Submitted data; excludes missing-trust estimates; geographic parent is a source ICB, not a hospital site
B16: RTT 18-week performance | C16: Share of incomplete pathways waiting within 18 weeks | D16: SUM(within_18) | E16: SUM(waiting_count) | F16: Weighted ratio; exactly 18 weeks is included; published 92% standard is a benchmark, not a newly inferred target
B17: RTT long-wait share | C17: Share strictly over 52 weeks | D17: SUM(over_52) | E17: SUM(waiting_count) | F17: Volume and rate support different operational questions
B18: Admitted completed pathways | C18: Monthly completed RTT pathways; separate from the month-end incomplete stock | D18: SUM(total_all) | E18: Not applicable | F18: Includes completed pathways with unknown start; known-start measures use waiting_count
B19: Non-admitted completed pathways | C19: Monthly completed RTT pathways; separate from the month-end incomplete stock | D19: SUM(total_all) | E19: Not applicable | F19: Includes completed pathways with unknown start; known-start measures use waiting_count
... B41: Latest reporting period | C41: Most recent retained source reporting month | D41: MAX(reporting_month) | E41: Not applicable | F41: Never relabel as current live patient data

Sheet Data Quality Summary
B2: NHS OPERATIONS | DATA QUALITY SUMMARY
B5: Published aggregate observations · independent portfolio analysis · source-specific reporting months
B8: Control | C8: Actual evidence | D8: Status
B9: rtt_consecutive_months | C9: 24 | D9: PASS
B10: rtt_audit_row_counts | C10: 236171 | D10: PASS
B11: ae_consecutive_months | C11: 25 | D11: PASS
B12: ae_audit_row_counts | C12: 4918 | D12: PASS
B13: diagnostics_consecutive_months | C13: 24 | D13: PASS
B14: diagnostics_audit_row_counts | C14: 162750 | D14: PASS
B18: RTT structural blanks resolve to zero only when observed nonnegative bands exhaust an explicit source total. Suppression remains missing. Historical publication dates that are not verified remain blank.
B23: Dataset | C23: Reporting month | D23: Publication date | E23: Source URL
B24: ae | C24: 2024-09 | E24: https://www.england.nhs.uk/statistics/wp-content/uploads/sites/2/2024/10/Monthly-AE-September-2024.csv
B25: ae | C25: 2024-10 | D25: 45792 | E25: https://www.england.nhs.uk/statistics/wp-content/uploads/sites/2/2025/05/Monthly-AE-October-2024-revised.csv
B26: ae | C26: 2024-11 | D26: 45792 | E26: https://www.england.nhs.uk/statistics/wp-content/uploads/sites/2/2025/05/Monthly-AE-November-2024-revised.csv
B27: ae | C27: 2024-12 | E27: https://www.england.nhs.uk/statistics/wp-content/uploads/sites/2/2025/01/Monthly-AE-December-2024.csv
B28: ae | C28: 2025-01 | E28: https://www.england.nhs.uk/statistics/wp-content/uploads/sites/2/2025/02/Monthly-AE-January-2025.csv
B29: ae | C29: 2025-02 | D29: 45792 | E29: https://www.england.nhs.uk/statistics/wp-content/uploads/sites/2/2025/05/Monthly-AE-February-2025-revised.csv
B30: ae | C30: 2025-03 | E30: https://www.england.nhs.uk/statistics/wp-content/uploads/sites/2/2025/04/Monthly-AE-March-2025.csv
B31: ae | C31: 2025-04 | D31: 45974 | E31: https://www.england.nhs.uk/statistics/wp-content/uploads/sites/2/2025/11/April-2025-CSV-revised.csv
B32: ae | C32: 2025-05 | D32: 45974 | E32: https://www.england.nhs.uk/statistics/wp-content/uploads/sites/2/2025/11/May-2025-CSV-revised.csv
B33: ae | C33: 2025-06 | D33: 45974 | E33: https://www.england.nhs.uk/statistics/wp-content/uploads/sites/2/2025/11/June-2025-CSV-revised.csv
B34: ae | C34: 2025-07 | D34: 45974 | E34: https://www.england.nhs.uk/statistics/wp-content/uploads/sites/2/2025/11/July-2025-CSV-revised.csv
B35: ae | C35: 2025-08 | D35: 45974 | E35: https://www.england.nhs.uk/statistics/wp-content/uploads/sites/2/2025/11/August-2025-CSV-revised.csv
B36: ae | C36: 2025-09 | D36: 45974 | E36: https://www.england.nhs.uk/statistics/wp-content/uploads/sites/2/2025/11/September-2025-CSV-revised.csv
B37: ae | C37: 2025-10 | D37: 46156 | E37: https://www.england.nhs.uk/statistics/wp-content/uploads/sites/2/2026/05/Monthly-AE-October-2025-revised-fly02sk.csv
B38: ae | C38: 2025-11 | D38: 46156 | E38: https://www.england.nhs.uk/statistics/wp-content/uploads/sites/2/2026/05/Monthly-AE-Nov-25-CSV-revised.csv
B39: ae | C39: 2025-12 | D39: 46156 | E39: https://www.england.nhs.uk/statistics/wp-content/uploads/sites/2/2026/05/Monthly-AE-December-2025-revised-g9Hy6.csv
B40: ae | C40: 2026-01 | D40: 46156 | E40: https://www.england.nhs.uk/statistics/wp-content/uploads/sites/2/2026/05/Monthly-AE-January-2026-revised-3dker.csv
B41: ae | C41: 2026-02 | E41: https://www.england.nhs.uk/statistics/wp-content/uploads/sites/2/2026/03/February-2026-CSV-Dl8t54.csv
B42: ae | C42: 2026-03 | D42: 46156 | E42: https://www.england.nhs.uk/statistics/wp-content/uploads/sites/2/2026/05/Monthly-AE-March-2026-revised-flkg42.csv
B43: ae | C43: 2026-04 | E43: https://www.england.nhs.uk/statistics/wp-content/uploads/sites/2/2026/05/April-2026-CSV-QD21vf.csv
B44: ae | C44: 2026-05 | E44: https://www.england.nhs.uk/statistics/wp-content/uploads/sites/2/2026/06/May-2026-CSV-F4flrg.csv
B45: ae | C45: 2026-06 | E45: https://www.england.nhs.uk/statistics/wp-content/uploads/sites/2/2026/07/June-2026-CSV-Wfg38l.csv
B46: ae | C46: 2026-07 | E46: https://www.england.nhs.uk/statistics/wp-content/uploads/sites/2/2026/08/July-2026-CSV-Trf28h.csv
B47: ae | C47: 2026-08 | E47: https://www.england.nhs.uk/statistics/wp-content/uploads/sites/2/2026/09/August-2026-CSV-De2k3n.csv
B48: ae | C48: 2026-09 | D48: 46303 | E48: https://www.england.nhs.uk/statistics/wp-content/uploads/sites/2/2026/10/September-2026-CSV-Re72Eh.csv
B49: diagnostics | C49: 2024-09 | D49: 45848 | E49: https://www.england.nhs.uk/statistics/wp-content/uploads/sites/2/2025/07/DM01-SEPTEMBER-2024-full-extract.zip
B50: diagnostics | C50: 2024-10 | D50: 45848 | E50: https://www.england.nhs.uk/statistics/wp-content/uploads/sites/2/2025/07/DM01-OCTOBER-2024-full-extract.zip
B51: diagnostics | C51: 2024-11 | D51: 45848 | E51: https://www.england.nhs.uk/statistics/wp-content/uploads/sites/2/2025/07/DM01-NOVEMBER-2024-full-extract.zip
B52: diagnostics | C52: 2024-12 | D52: 45848 | E52: https://www.england.nhs.uk/statistics/wp-content/uploads/sites/2/2025/07/DM01-DECEMBER-2024-full-extract.zip
...

Sheet Scenario Analysis
B2: NHS OPERATIONS | SCENARIO ANALYSIS
B5: Published aggregate observations · independent portfolio analysis · source-specific reporting months
B8: Scenario input | C8: Value | D8: Units | E8: Meaning
B9: Current over52 | C9: 109936 | D9: pathways | E9: Validated submitted count
B10: Hypothetical reduction | C10: 0.1 | D10: percent | E10: Editable planning assumption
B11: Illustrative residual | C11: =C9*(1-C10) -> 98942.4 | D11: pathways | E11: Arithmetic scenario, not a forecast or delivered benefit
B15: This scenario shows the arithmetic effect of a hypothetical reduction. It does not model capacity, causality, savings or future patient outcomes.

Sheet Source Data
B2: NHS OPERATIONS | SOURCE DATA
B5: Published aggregate observations · independent portfolio analysis · source-specific reporting months
B8: Month | C8: RTT waiting | D8: RTT within18 | E8: RTT over52 | F8: AE attendances | G8: AE within4 | H8: Emergency admissions | I8: DTA12plus | J8: Diagnostic waiting | K8: Diagnostic over6 | L8: Diagnostic activity | P8: Month | Q8: RTT rate chart | R8: AE rate chart
B9: 2024-09 | C9: 7571549 | D9: 4429902 | E9: 249024 | F9: 2214217 | G9: 1643329 | H9: 530824 | I9: 38880 | J9: 1592553 | K9: 361264 | L9: 2393472 | P9: ='Monthly Trends'!B9 -> 2024-09 | Q9: =IF(ISNUMBER('Monthly Trends'!C9),'Monthly Trends'!C9,NA()) -> 0.58507209 | R9: =IF(ISNUMBER('Monthly Trends'!D9),'Monthly Trends'!D9,NA()) -> 0.74217161
B10: 2024-10 | C10: 7541371 | D10: 4444500 | E10: 234914 | F10: 2360536 | G10: 1725194 | H10: 567448 | I10: 49616 | J10: 1636424 | K10: 338730 | L10: 2568267 | P10: ='Monthly Trends'!B10 -> 2024-10 | Q10: =IF(ISNUMBER('Monthly Trends'!C10),'Monthly Trends'!C10,NA()) -> 0.58934907 | R10: =IF(ISNUMBER('Monthly Trends'!D10),'Monthly Trends'!D10,NA()) -> 0.73084842
B11: 2024-11 | C11: 7479867 | D11: 4424701 | E11: 221567 | F11: 2314998 | G11: 1671002 | H11: 552161 | I11: 45791 | J11: 1620824 | K11: 322929 | L11: 2465088 | P11: ='Monthly Trends'!B11 -> 2024-11 | Q11: =IF(ISNUMBER('Monthly Trends'!C11),'Monthly Trends'!C11,NA()) -> 0.59154809 | R11: =IF(ISNUMBER('Monthly Trends'!D11),'Monthly Trends'!D11,NA()) -> 0.72181574
B12: 2024-12 | C12: 7463085 | D12: 4398544 | E12: 200402 | F12: 2345934 | G12: 1668461 | H12: 552592 | I12: 54207 | J12: 1568661 | K12: 357119 | L12: 2257697 | P12: ='Monthly Trends'!B12 -> 2024-12 | Q12: =IF(ISNUMBER('Monthly Trends'!C12),'Monthly Trends'!C12,NA()) -> 0.58937343 | R12: =IF(ISNUMBER('Monthly Trends'!D12),'Monthly Trends'!D12,NA()) -> 0.71121396
B13: 2025-01 | C13: 7427669 | D13: 4371844 | E13: 198828 | F13: 2218130 | G13: 1619384 | H13: 548775 | I13: 61529 | J13: 1627995 | K13: 365178 | L13: 2539567 | P13: ='Monthly Trends'!B13 -> 2025-01 | Q13: =IF(ISNUMBER('Monthly Trends'!C13),'Monthly Trends'!C13,NA()) -> 0.58858896 | R13: =IF(ISNUMBER('Monthly Trends'!D13),'Monthly Trends'!D13,NA()) -> 0.73006722
B14: 2025-02 | C14: 7401153 | D14: 4379951 | E14: 193525 | F14: 2088071 | G14: 1533925 | H14: 496095 | I14: 47623 | J14: 1674823 | K14: 292432 | L14: 2354255 | P14: ='Monthly Trends'!B14 -> 2025-02 | Q14: =IF(ISNUMBER('Monthly Trends'!C14),'Monthly Trends'!C14,NA()) -> 0.59179306 | R14: =IF(ISNUMBER('Monthly Trends'!D14),'Monthly Trends'!D14,NA()) -> 0.73461343
B15: 2025-03 | C15: 7418598 | D15: 4434722 | E15: 180243 | F15: 2389064 | G15: 1791316 | H15: 551129 | I15: 46766 | J15: 1709380 | K15: 313990 | L15: 2526281 | P15: ='Monthly Trends'!B15 -> 2025-03 | Q15: =IF(ISNUMBER('Monthly Trends'!C15),'Monthly Trends'!C15,NA()) -> 0.59778438 | R15: =IF(ISNUMBER('Monthly Trends'!D15),'Monthly Trends'!D15,NA()) -> 0.74979825
B16: 2025-04 | C16: 7389065 | D16: 4413682 | E16: 190023 | F16: 2297421 | G16: 1718099 | H16: 528230 | I16: 44648 | J16: 1703100 | K16: 361993 | L16: 2429486 | P16: ='Monthly Trends'!B16 -> 2025-04 | Q16: =IF(ISNUMBER('Monthly Trends'!C16),'Monthly Trends'!C16,NA()) -> 0.59732618 | R16: =IF(ISNUMBER('Monthly Trends'!D16),'Monthly Trends'!D16,NA()) -> 0.74783812
B17: 2025-05 | C17: 7355950 | D17: 4482076 | E17: 196839 | F17: 2397529 | G17: 1807794 | H17: 545128 | I17: 42891 | J17: 1715934 | K17: 378352 | L17: 2500593 | P17: ='Monthly Trends'!B17 -> 2025-05 | Q17: =IF(ISNUMBER('Monthly Trends'!C17),'Monthly Trends'!C17,NA()) -> 0.60931301 | R17: =IF(ISNUMBER('Monthly Trends'!D17),'Monthly Trends'!D17,NA()) -> 0.75402383
B18: 2025-06 | C18: 7367836 | D18: 4533070 | E18: 191755 | F18: 2351581 | G18: 1776772 | H18: 535941 | I18: 38683 | J18: 1739272 | K18: 370874 | L18: 2529788 | P18: ='Monthly Trends'!B18 -> 2025-06 | Q18: =IF(ISNUMBER('Monthly Trends'!C18),'Monthly Trends'!C18,NA()) -> 0.61525121 | R18: =IF(ISNUMBER('Monthly Trends'!D18),'Monthly Trends'!D18,NA()) -> 0.75556487
B19: 2025-07 | C19: 7299023 | D19: 4468469 | E19: 189416 | F19: 2408866 | G19: 1840562 | H19: 559392 | I19: 35467 | J19: 1753665 | K19: 383518 | L19: 2662297 | P19: ='Monthly Trends'!B19 -> 2025-07 | Q19: =IF(ISNUMBER('Monthly Trends'!C19),'Monthly Trends'!C19,NA()) -> 0.61220098 | R19: =IF(ISNUMBER('Monthly Trends'!D19),'Monthly Trends'!D19,NA()) -> 0.7640782
B20: 2025-08 | C20: 7312356 | D20: 4458454 | E20: 188702 | F20: 2266937 | G20: 1720066 | H20: 526399 | I20: 35909 | J20: 1683852 | K20: 404795 | L20: 2422424 | P20: ='Monthly Trends'!B20 -> 2025-08 | Q20: =IF(ISNUMBER('Monthly Trends'!C20),'Monthly Trends'!C20,NA()) -> 0.60971512 | R20: =IF(ISNUMBER('Monthly Trends'!D20),'Monthly Trends'!D20,NA()) -> 0.75876215
... B32: 2026-08 | C32: 7158164 | D32: 4667554 | E32: 109936 | F32: 2342959 | G32: 1758192 | H32: 517868 | I32: 44951 | J32: 1833070 | K32: 452306 | L32: 2516963 | P32: ='Monthly Trends'!B32 -> 2026-08 | Q32: =IF(ISNUMBER('Monthly Trends'!C32),'Monthly Trends'!C32,NA()) -> 0.65206022 | R32: =IF(ISNUMBER('Monthly Trends'!D32),'Monthly Trends'!D32,NA()) -> 0.75041518
B33: 2026-09 | F33: 2444743 | G33: 1817992 | H33: 536158 | I33: 50582 | P33: ='Monthly Trends'!B33 -> 2026-09 | Q33: =IF(ISNUMBER('Monthly Trends'!C33),'Monthly Trends'!C33,NA()) -> #N/A | R33: =IF(ISNUMBER('Monthly Trends'!D33),'Monthly Trends'!D33,NA()) -> 0.74363318
